<br/>

<!-- tabs:start -->

#### **捕获异常**

```csharp
try:
    n = 1/0

except ZeroDivisionError as msg:
    print(msg)

except (AssertionError, TypeError) as msg:
    print(msg)

except Exception as msg:
    print(msg)

finally:
    print('finally')
        
        
```



#### **抛出异常**

```shell
x = 10
if x > 5:
   raise Exception('x 不能大于 5。x 的值为: { 10 }')
    
        
```

>[!WARNING|style: flat|label: 简要说明 ]
>
>- 通过断言方式[`assert False`抛出`AssertionError` ]
>
>```shell
>x = 10
>
># if x < 5:
>#    raise AssertionError('x 不能大于 5。x 的值为: { 10 }')
>assert x < 5, 'x 不能大于 5。x 的值为: { 10 }'
>    
>    
>```
>
>
>
><br/>



#### **[ ☢ with ]using**

!> (`Python`)中的`with`语句用于异常处理 <span style='color:red'>[ 封装了`try…except…finally`编码范式，提高了易用性 ]</span>

```shell
# file = open('./test_runoob.txt', 'w')
# try:
#     file.write('hello world')
# finally:
#     file.close()

with open('./test_runoob.txt', 'w') as file:
    file.write('hello world !')
        
        
```



<!-- tabs:end -->



